Workbook
Name Dependent_Variable: 'Cleaned Data'!$T$1:$T$1001
Name Independent_Variables: 'Cleaned Data'!$I$1:$S$1001
Name Numerical_Data: 'Cleaned Data'!$E$1:$T$1001

Sheet Index
A1: INDEX
A4: S.No | B4: Topic
A5: 1 | B5: Original Data from Kaggel
A6: 2 | B6: Data Cleaning Log and Pre-Processing
A7: 3 | B7: Processed Data (Cleaned)
A8: 4 | B8: Descriptive Statistics
A9: 5 | B9: Correlation Matrix
A10: 6 | B10: Regression Model 1 (High Multicollinearity)
A11: 7 | B11: Regression Model 2 (High Multicollinearity)
A12: 8 | B12: Regression Model 3 (Low Multicollinearity)
A13: 9 | B13: Multicollinearity Test for Model 1
A14: 10 | B14: Multicollinearity Test for Model 2
A15: 11 | B15: Multicollinearity Test for Model 3 (Final)
A16: 12 | B16: Results of Multicollinearity Testing

Sheet Original Data
A1: User_ID | B1: Age | C1: Gender | D1: Platform | E1: Daily_Usage_Time (minutes) | F1: Posts_Per_Day | G1: Likes_Received_Per_Day | H1: Comments_Received_Per_Day | I1: Messages_Sent_Per_Day | J1: Dominant_Emotion
A3: 1 | B3: 25 | C3: Female | D3: Instagram | E3: 120 | F3: 3 | G3: 45 | H3: 10 | I3: 12 | J3: Happiness | O3: BACK TO INDEX
A5: 2 | B5: 30 | C5: Male | D5: Twitter | E5: 90 | F5: 5 | G5: 20 | H5: 25 | I5: 30 | J5: Anger
A7: 3 | B7: 22 | C7: Non-binary | D7: Facebook | E7: 60 | F7: 2 | G7: 15 | H7: 5 | I7: 20 | J7: Neutral
A9: 4 | B9: 28 | C9: Female | D9: Instagram | E9: 200 | F9: 8 | G9: 100 | H9: 30 | I9: 50 | J9: Anxiety
A11: 5 | B11: 33 | C11: Male | D11: LinkedIn | E11: 45 | F11: 1 | G11: 5 | H11: 2 | I11: 10 | J11: Boredom
A13: 6 | B13: 21 | C13: Male | D13: Instagram | E13: 150 | F13: 4 | G13: 60 | H13: 15 | I13: 25 | J13: Happiness
A15: 7 | B15: 27 | C15: Female | D15: Twitter | E15: 85 | F15: 3 | G15: 30 | H15: 10 | I15: 18 | J15: Anger
A17: 8 | B17: 24 | C17: Non-binary | D17: Facebook | E17: 110 | F17: 6 | G17: 25 | H17: 12 | I17: 22 | J17: Sadness
A19: 9 | B19: 29 | C19: Female | D19: LinkedIn | E19: 55 | F19: 2 | G19: 10 | H19: 3 | I19: 8 | J19: Neutral
A21: 10 | B21: 31 | C21: Male | D21: Instagram | E21: 170 | F21: 5 | G21: 80 | H21: 20 | I21: 35 | J21: Happiness
A23: 11 | B23: 23 | C23: Female | D23: Twitter | E23: 75 | F23: 4 | G23: 35 | H23: 7 | I23: 20 | J23: Anxiety
A25: 12 | B25: 26 | C25: Non-binary | D25: Facebook | E25: 95 | F25: 3 | G25: 20 | H25: 10 | I25: 18 | J25: Sadness
A27: 13 | B27: 34 | C27: Male | D27: LinkedIn | E27: 65 | F27: 1 | G27: 12 | H27: 4 | I27: 15 | J27: Boredom
... A501: 250 | B501: 28 | C501: Female | D501: LinkedIn | E501: 55 | F501: 1 | G501: 12 | H501: 6 | I501: 10 | J501: Boredom
A503: 251 | B503: Male | C503: 27 | D503: Instagram | E503: 165 | F503: 6 | G503: 85 | H503: 30 | I503: 28 | J503: Happiness
A505: 252 | B505: Female | C505: 24 | D505: Twitter | E505: 75 | F505: 3 | G505: 33 | H505: 18 | I505: 19 | J505: Anger
A507: 253 | B507: Non-binary | C507: 29 | D507: Facebook | E507: 85 | F507: 2 | G507: 27 | H507: 9 | I507: 20 | J507: Neutral
A509: 254 | B509: Female | C509: 33 | D509: Instagram | E509: 145 | F509: 4 | G509: 65 | H509: 23 | I509: 35 | J509: Sadness
A511: 255 | B511: Male | C511: 31 | D511: LinkedIn | E511: 60 | F511: 1 | G511: 15 | H511: 7 | I511: 17 | J511: Anxiety
A513: 256 | B513: Female | C513: 22 | D513: Whatsapp | E513: 70 | F513: 2 | G513: 42 | H513: 10 | I513: 21 | J513: Anxiety
A515: 257 | B515: Male | C515: 25 | D515: Telegram | E515: 90 | F515: 3 | G515: 22 | H515: 11 | I515: 22 | J515: Boredom
A517: 258 | B517: Non-binary | C517: 29 | D517: Snapchat | E517: 50 | F517: 2 | G517: 18 | H517: 7 | I517: 18 | J517: Sadness
A519: 259 | B519: Female | C519: 28 | D519: Twitter | E519: 95 | F519: 4 | G519: 48 | H519: 22 | I519: 25 | J519: Happiness
A521: 260 | B521: Male | C521: 27 | D521: Facebook | E521: 60 | F521: 1 | G521: 12 | H521: 5 | I521: 15 | J521: Boredom
A523: 261 | B523: Female | C523: 30 | D523: Instagram | E523: 175 | F523: 6 | G523: 72 | H523: 30 | I523: 33 | J523: Happiness
A525: 262 | B525: Male | C525: 23 | D525: Whatsapp | E525: 70 | F525: 3 | G525: 22 | H525: 10 | I525: 18 | J525: Anger
... A577: 288 | B577: Non-binary | C577: 21 | D577: Snapchat | E577: 60 | F577: 1 | G577: 18 | H577: 7 | I577: 12 | J577: Neutral
A579: 289 | B579: 25 | C579: Female | D579: Instagram | E579: 170 | F579: 6 | G579: 83 | H579: 30 | I579: 33 | J579: Happiness
A581: 290 | B581: 30 | C581: Male | D581: Twitter | E581: 70 | F581: 2 | G581: 30 | H581: 12 | I581: 20 | J581: Anxiety
A583: 291 | B583: 27 | C583: Non-binary | D583: Facebook | E583: 50 | F583: 1 | G583: 10 | H583: 4 | I583: 10 | J583: Boredom
A585: 292 | B585: 32 | C585: Female | D585: Whatsapp | E585: 105 | F585: 4 | G585: 55 | H585: 25 | I585: 25 | J585: Anger
A587: 293 | B587: 24 | C587: Male | D587: Telegram | E587: 75 | F587: 3 | G587: 37 | H587: 16 | I587: 22 | J587: Neutral
A589: 294 | B589: 29 | C589: Female | D589: Snapchat | E589: 95 | F589: 2 | G589: 23 | H589: 10 | I589: 28 | J589: Sadness
A591: 295 | B591: 26 | C591: Male | D591: Instagram | E591: 150 | F591: 5 | G591: 70 | H591: 25 | I591: 30 | J591: Anxiety
A593: 296 | B593: 33 | C593: Non-binary | D593: Twitter | E593: 85 | F593: 4 | G593: 35 | H593: 18 | I593: 18 | J593: Boredom
A595: 297 | B595: 22 | C595: Female | D595: Facebook | E595: 70 | F595: 1 | G595: 14 | H595: 6 | I595: 10 | J595: Neutral
A597: 298 | B597: 35 | C597: Male | D597: Whatsapp | E597: 110 | F597: 3 | G597: 50 | H597: 25 | I597: 25 | J597: Happiness
A599: 299 | B599: 28 | C599: Non-binary | D599: Telegram | E599: 60 | F599: 2 | G599: 18 | H599: 8 | I599: 18 | J599: Anger
A601: 300 | B601: 27 | C601: Female | D601: Snapchat | E601: 120 | F601: 4 | G601: 40 | H601: 18 | I601: 22 | J601: Neutral
...

Sheet Cleaning & Variable Conversion
A2: Gender (Non-binary as reference) | E2: BACK TO INDEX
A3: Male | B3: Dummy Variables
A4: Female
A6: Platform (Telegram as reference)
A7: Twitter | B7: Dummy Variables
A8: Snapchat
A9: WhatsApp
A10: LinkedIn
A11: Facebook
A12: Instagram
A14: Dominant Emotion (Binary conversion)
A15: Happy | B15: 1
A16: Not Happy (Rest all emotions) | B16: 0
A18: Engagement Score (Combined Column)
A19: Posts_Per_Day | B19: Standardization (X - mean) / stddev
A20: Likes_Received_Per_Day
A21: Comments_Received_Per_Day
A22: Messages_Sent_Per_Day

Sheet Cleaned Data
A1: User_ID | B1: Platform | C1: Gender | D1: Dominant_Emotion | E1: Gender_Male | F1: Gender_Female | G1: Age | H1: Likes_Received_Per_Day | I1: Instagram_Platform | J1: Comments_Received_Per_Day | K1: Messages_Sent_Per_Day | L1: Posts_Per_Day | M1: Happiness_Emotion | N1: Twitter_Platform | O1: Facebook_Platform | P1: LinkedIn_Platform | Q1: Snapchat_Platform | R1: Whatsapp_Platform | S1: Engagement_Score_Per_Day | T1: Daily_Usage_Time (minutes)
A2: 1 | B2: Instagram | C2: Female | D2: Happiness | E2: =IF(C2="Male",1,0) -> 0 | F2: =IF(C2="Female",1,0) -> 1 | G2: 25 | H2: 45 | I2: =IF(B2="Instagram",1,0) -> 1 | J2: 10 | K2: 12 | L2: 3 | M2: {=_xlfn.SWITCH(D2,"Happiness",1,0)} -> 1 | N2: =IF(B2="Twitter",1,0) -> 0 | O2: =IF(B2="Facebook",1,0) -> 0 | P2: =IF(B2="LinkedIn",1,0) -> 0 | Q2: =IF(B2="Snapchat",1,0) -> 0 | R2: =IF(B2="Whatsapp",1,0) -> 0 | S2: =(J2-AVERAGE(J$2:J$1001))/STDEV(J$2:J$1001) +(K2-AVERAGE(K$2:K$1001))/STDEV(K$2:K$1001) +(L2-AVERAGE(L$2:L$1001))/STDEV(L$2:L$1001) +(H2-AVERAGE(H$2:H$1001))/STDEV(H$2:H$1001) -> -1.8505413 | T2: 120 | W2: BACK TO INDEX
A3: 2 | B3: Twitter | C3: Male | D3: Anger | E3: =IF(C3="Male",1,0) -> 1 | F3: =IF(C3="Female",1,0) -> 0 | G3: 30 | H3: 20 | I3: =IF(B3="Instagram",1,0) -> 0 | J3: 25 | K3: 30 | L3: 5 | M3: {=_xlfn.SWITCH(D3,"Happiness",1,0)} -> 0 | N3: =IF(B3="Twitter",1,0) -> 1 | O3: =IF(B3="Facebook",1,0) -> 0 | P3: =IF(B3="LinkedIn",1,0) -> 0 | Q3: =IF(B3="Snapchat",1,0) -> 0 | R3: =IF(B3="Whatsapp",1,0) -> 0 | S3: =(J3-AVERAGE(J$2:J$1001))/STDEV(J$2:J$1001) +(K3-AVERAGE(K$2:K$1001))/STDEV(K$2:K$1001) +(L3-AVERAGE(L$2:L$1001))/STDEV(L$2:L$1001) +(H3-AVERAGE(H$2:H$1001))/STDEV(H$2:H$1001) -> 2.0612616 | T3: 90
A4: 3 | B4: Facebook | C4: Non-binary | D4: Neutral | E4: =IF(C4="Male",1,0) -> 0 | F4: =IF(C4="Female",1,0) -> 0 | G4: 22 | H4: 15 | I4: =IF(B4="Instagram",1,0) -> 0 | J4: 5 | K4: 20 | L4: 2 | M4: {=_xlfn.SWITCH(D4,"Happiness",1,0)} -> 0 | N4: =IF(B4="Twitter",1,0) -> 0 | O4: =IF(B4="Facebook",1,0) -> 1 | P4: =IF(B4="LinkedIn",1,0) -> 0 | Q4: =IF(B4="Snapchat",1,0) -> 0 | R4: =IF(B4="Whatsapp",1,0) -> 0 | S4: =(J4-AVERAGE(J$2:J$1001))/STDEV(J$2:J$1001) +(K4-AVERAGE(K$2:K$1001))/STDEV(K$2:K$1001) +(L4-AVERAGE(L$2:L$1001))/STDEV(L$2:L$1001) +(H4-AVERAGE(H$2:H$1001))/STDEV(H$2:H$1001) -> -3.1370243 | T4: 60
A5: 4 | B5: Instagram | C5: Female | D5: Anxiety | E5: =IF(C5="Male",1,0) -> 0 | F5: =IF(C5="Female",1,0) -> 1 | G5: 28 | H5: 100 | I5: =IF(B5="Instagram",1,0) -> 1 | J5: 30 | K5: 50 | L5: 8 | M5: {=_xlfn.SWITCH(D5,"Happiness",1,0)} -> 0 | N5: =IF(B5="Twitter",1,0) -> 0 | O5: =IF(B5="Facebook",1,0) -> 0 | P5: =IF(B5="LinkedIn",1,0) -> 0 | Q5: =IF(B5="Snapchat",1,0) -> 0 | R5: =IF(B5="Whatsapp",1,0) -> 0 | S5: =(J5-AVERAGE(J$2:J$1001))/STDEV(J$2:J$1001) +(K5-AVERAGE(K$2:K$1001))/STDEV(K$2:K$1001) +(L5-AVERAGE(L$2:L$1001))/STDEV(L$2:L$1001) +(H5-AVERAGE(H$2:H$1001))/STDEV(H$2:H$1001) -> 9.5745611 | T5: 200
A6: 5 | B6: LinkedIn | C6: Male | D6: Boredom | E6: =IF(C6="Male",1,0) -> 1 | F6: =IF(C6="Female",1,0) -> 0 | G6: 33 | H6: 5 | I6: =IF(B6="Instagram",1,0) -> 0 | J6: 2 | K6: 10 | L6: 1 | M6: {=_xlfn.SWITCH(D6,"Happiness",1,0)} -> 0 | N6: =IF(B6="Twitter",1,0) -> 0 | O6: =IF(B6="Facebook",1,0) -> 0 | P6: =IF(B6="LinkedIn",1,0) -> 1 | Q6: =IF(B6="Snapchat",1,0) -> 0 | R6: =IF(B6="Whatsapp",1,0) -> 0 | S6: =(J6-AVERAGE(J$2:J$1001))/STDEV(J$2:J$1001) +(K6-AVERAGE(K$2:K$1001))/STDEV(K$2:K$1001) +(L6-AVERAGE(L$2:L$1001))/STDEV(L$2:L$1001) +(H6-AVERAGE(H$2:H$1001))/STDEV(H$2:H$1001) -> -5.5525853 | T6: 45
A7: 6 | B7: Instagram | C7: Male | D7: Happiness | E7: =IF(C7="Male",1,0) -> 1 | F7: =IF(C7="Female",1,0) -> 0 | G7: 21 | H7: 60 | I7: =IF(B7="Instagram",1,0) -> 1 | J7: 15 | K7: 25 | L7: 4 | M7: {=_xlfn.SWITCH(D7,"Happiness",1,0)} -> 1 | N7: =IF(B7="Twitter",1,0) -> 0 | O7: =IF(B7="Facebook",1,0) -> 0 | P7: =IF(B7="LinkedIn",1,0) -> 0 | Q7: =IF(B7="Snapchat",1,0) -> 0 | R7: =IF(B7="Whatsapp",1,0) -> 0 | S7: =(J7-AVERAGE(J$2:J$1001))/STDEV(J$2:J$1001) +(K7-AVERAGE(K$2:K$1001))/STDEV(K$2:K$1001) +(L7-AVERAGE(L$2:L$1001))/STDEV(L$2:L$1001) +(H7-AVERAGE(H$2:H$1001))/STDEV(H$2:H$1001) -> 1.3334948 | T7: 150
A8: 7 | B8: Twitter | C8: Female | D8: Anger | E8: =IF(C8="Male",1,0) -> 0 | F8: =IF(C8="Female",1,0) -> 1 | G8: 27 | H8: 30 | I8: =IF(B8="Instagram",1,0) -> 0 | J8: 10 | K8: 18 | L8: 3 | M8: {=_xlfn.SWITCH(D8,"Happiness",1,0)} -> 0 | N8: =IF(B8="Twitter",1,0) -> 1 | O8: =IF(B8="Facebook",1,0) -> 0 | P8: =IF(B8="LinkedIn",1,0) -> 0 | Q8: =IF(B8="Snapchat",1,0) -> 0 | R8: =IF(B8="Whatsapp",1,0) -> 0 | S8: =(J8-AVERAGE(J$2:J$1001))/STDEV(J$2:J$1001) +(K8-AVERAGE(K$2:K$1001))/STDEV(K$2:K$1001) +(L8-AVERAGE(L$2:L$1001))/STDEV(L$2:L$1001) +(H8-AVERAGE(H$2:H$1001))/STDEV(H$2:H$1001) -> -1.7143217 | T8: 85
A9: 8 | B9: Facebook | C9: Non-binary | D9: Sadness | E9: =IF(C9="Male",1,0) -> 0 | F9: =IF(C9="Female",1,0) -> 0 | G9: 24 | H9: 25 | I9: =IF(B9="Instagram",1,0) -> 0 | J9: 12 | K9: 22 | L9: 6 | M9: {=_xlfn.SWITCH(D9,"Happiness",1,0)} -> 0 | N9: =IF(B9="Twitter",1,0) -> 0 | O9: =IF(B9="Facebook",1,0) -> 1 | P9: =IF(B9="LinkedIn",1,0) -> 0 | Q9: =IF(B9="Snapchat",1,0) -> 0 | R9: =IF(B9="Whatsapp",1,0) -> 0 | S9: =(J9-AVERAGE(J$2:J$1001))/STDEV(J$2:J$1001) +(K9-AVERAGE(K$2:K$1001))/STDEV(K$2:K$1001) +(L9-AVERAGE(L$2:L$1001))/STDEV(L$2:L$1001) +(H9-AVERAGE(H$2:H$1001))/STDEV(H$2:H$1001) -> 0.35962126 | T9: 110
A10: 9 | B10: LinkedIn | C10: Female | D10: Neutral | E10: =IF(C10="Male",1,0) -> 0 | F10: =IF(C10="Female",1,0) -> 1 | G10: 29 | H10: 10 | I10: =IF(B10="Instagram",1,0) -> 0 | J10: 3 | K10: 8 | L10: 2 | M10: {=_xlfn.SWITCH(D10,"Happiness",1,0)} -> 0 | N10: =IF(B10="Twitter",1,0) -> 0 | O10: =IF(B10="Facebook",1,0) -> 0 | P10: =IF(B10="LinkedIn",1,0) -> 1 | Q10: =IF(B10="Snapchat",1,0) -> 0 | R10: =IF(B10="Whatsapp",1,0) -> 0 | S10: =(J10-AVERAGE(J$2:J$1001))/STDEV(J$2:J$1001) +(K10-AVERAGE(K$2:K$1001))/STDEV(K$2:K$1001) +(L10-AVERAGE(L$2:L$1001))/STDEV(L$2:L$1001) +(H10-AVERAGE(H$2:H$1001))/STDEV(H$2:H$1001) -> -4.9622995 | T10: 55
A11: 10 | B11: Instagram | C11: Male | D11: Happiness | E11: =IF(C11="Male",1,0) -> 1 | F11: =IF(C11="Female",1,0) -> 0 | G11: 31 | H11: 80 | I11: =IF(B11="Instagram",1,0) -> 1 | J11: 20 | K11: 35 | L11: 5 | M11: {=_xlfn.SWITCH(D11,"Happiness",1,0)} -> 1 | N11: =IF(B11="Twitter",1,0) -> 0 | O11: =IF(B11="Facebook",1,0) -> 0 | P11: =IF(B11="LinkedIn",1,0) -> 0 | Q11: =IF(B11="Snapchat",1,0) -> 0 | R11: =IF(B11="Whatsapp",1,0) -> 0 | S11: =(J11-AVERAGE(J$2:J$1001))/STDEV(J$2:J$1001) +(K11-AVERAGE(K$2:K$1001))/STDEV(K$2:K$1001) +(L11-AVERAGE(L$2:L$1001))/STDEV(L$2:L$1001) +(H11-AVERAGE(H$2:H$1001))/STDEV(H$2:H$1001) -> 4.3547022 | T11: 170
A12: 11 | B12: Twitter | C12: Female | D12: Anxiety | E12: =IF(C12="Male",1,0) -> 0 | F12: =IF(C12="Female",1,0) -> 1 | G12: 23 | H12: 35 | I12: =IF(B12="Instagram",1,0) -> 0 | J12: 7 | K12: 20 | L12: 4 | M12: {=_xlfn.SWITCH(D12,"Happiness",1,0)} -> 0 | N12: =IF(B12="Twitter",1,0) -> 1 | O12: =IF(B12="Facebook",1,0) -> 0 | P12: =IF(B12="LinkedIn",1,0) -> 0 | Q12: =IF(B12="Snapchat",1,0) -> 0 | R12: =IF(B12="Whatsapp",1,0) -> 0 | S12: =(J12-AVERAGE(J$2:J$1001))/STDEV(J$2:J$1001) +(K12-AVERAGE(K$2:K$1001))/STDEV(K$2:K$1001) +(L12-AVERAGE(L$2:L$1001))/STDEV(L$2:L$1001) +(H12-AVERAGE(H$2:H$1001))/STDEV(H$2:H$1001) -> -1.1078877 | T12: 75
A13: 12 | B13: Facebook | C13: Non-binary | D13: Sadness | E13: =IF(C13="Male",1,0) -> 0 | F13: =IF(C13="Female",1,0) -> 0 | G13: 26 | H13: 20 | I13: =IF(B13="Instagram",1,0) -> 0 | J13: 10 | K13: 18 | L13: 3 | M13: {=_xlfn.SWITCH(D13,"Happiness",1,0)} -> 0 | N13: =IF(B13="Twitter",1,0) -> 0 | O13: =IF(B13="Facebook",1,0) -> 1 | P13: =IF(B13="LinkedIn",1,0) -> 0 | Q13: =IF(B13="Snapchat",1,0) -> 0 | R13: =IF(B13="Whatsapp",1,0) -> 0 | S13: =(J13-AVERAGE(J$2:J$1001))/STDEV(J$2:J$1001) +(K13-AVERAGE(K$2:K$1001))/STDEV(K$2:K$1001) +(L13-AVERAGE(L$2:L$1001))/STDEV(L$2:L$1001) +(H13-AVERAGE(H$2:H$1001))/STDEV(H$2:H$1001) -> -2.0931976 | T13: 95
A14: 13 | B14: LinkedIn | C14: Male | D14: Boredom | E14: =IF(C14="Male",1,0) -> 1 | F14: =IF(C14="Female",1,0) -> 0 | G14: 34 | H14: 12 | I14: =IF(B14="Instagram",1,0) -> 0 | J14: 4 | K14: 15 | L14: 1 | M14: {=_xlfn.SWITCH(D14,"Happiness",1,0)} -> 0 | N14: =IF(B14="Twitter",1,0) -> 0 | O14: =IF(B14="Facebook",1,0) -> 0 | P14: =IF(B14="LinkedIn",1,0) -> 1 | Q14: =IF(B14="Snapchat",1,0) -> 0 | R14: =IF(B14="Whatsapp",1,0) -> 0 | S14: =(J14-AVERAGE(J$2:J$1001))/STDEV(J$2:J$1001) +(K14-AVERAGE(K$2:K$1001))/STDEV(K$2:K$1001) +(L14-AVERAGE(L$2:L$1001))/STDEV(L$2:L$1001) +(H14-AVERAGE(H$2:H$1001))/STDEV(H$2:H$1001) -> -4.4734906 | T14: 65
... A1001: 1000 | B1001: Snapchat | C1001: Female | D1001: Neutral | E1001: =IF(C1001="Male",1,0) -> 0 | F1001: =IF(C1001="Female",1,0) -> 1 | G1001: 27 | H1001: 40 | I1001: =IF(B1001="Instagram",1,0) -> 0 | J1001: 18 | K1001: 22 | L1001: 4 | M1001: {=_xlfn.SWITCH(D1001,"Happiness",1,0)} -> 0 | N1001: =IF(B1001="Twitter",1,0) -> 0 | O1001: =IF(B1001="Facebook",1,0) -> 0 | P1001: =IF(B1001="LinkedIn",1,0) -> 0 | Q1001: =IF(B1001="Snapchat",1,0) -> 1 | R1001: =IF(B1001="Whatsapp",1,0) -> 0 | S1001: =(J1001-AVERAGE(J$2:J$1001))/STDEV(J$2:J$1001) +(K1001-AVERAGE(K$2:K$1001))/STDEV(K$2:K$1001) +(L1001-AVERAGE(L$2:L$1001))/STDEV(L$2:L$1001) +(H1001-AVERAGE(H$2:H$1001))/STDEV(H$2:H$1001) -> 0.5636319 | T1001: 120

Sheet Descriptive Statistics
A1: Gender_Male | C1: Gender_Female | E1: Age | G1: Comments_Received_Per_Day | I1: Messages_Sent_Per_Day | K1: Posts_Per_Day | M1: Likes_Received_Per_Day | O1: Twitter_Platform | Q1: Facebook_Platform | S1: LinkedIn_Platform | U1: Snapchat_Platform | W1: Whatsapp_Platform | Y1: Instagram_Platform | AA1: Engagement_Score_Per_Day | AC1: Happiness_Emotion | AE1: Daily_Usage_Time (minutes)
A3: Mean | B3: 0.36 | C3: Mean | D3: 0.37 | E3: Mean | F3: 27.51 | G3: Mean | H3: 15.611 | I3: Mean | J3: 22.56 | K3: Mean | L3: 3.321 | M3: Mean | N3: 39.898 | O3: Mean | P3: 0.2 | Q3: Mean | R3: 0.19 | S3: Mean | T3: 0.12 | U3: Mean | V3: 0.08 | W3: Mean | X3: 0.08 | Y3: Mean | Z3: 0.25 | AA3: Mean | AB3: 5.5622174e-17 | AC3: Mean | AD3: 0.2 | AE3: Mean | AF3: 95.95
A4: Standard Error | B4: 0.015186528 | C4: Standard Error | D4: 0.015275252 | E4: Standard Error | F4: 0.1242793 | G4: Standard Error | H4: 0.27889687 | I4: Standard Error | J4: 0.26930824 | K4: Standard Error | L4: 0.060544402 | M4: Standard Error | N4: 0.83464737 | O4: Standard Error | P4: 0.01265544 | Q4: Standard Error | R4: 0.012411851 | S4: Standard Error | T4: 0.010281328 | U4: Standard Error | V4: 0.008583337 | W4: Standard Error | X4: 0.008583337 | Y4: Standard Error | Z4: 0.013699916 | AA4: Standard Error | AB4: 0.1219403 | AC4: Standard Error | AD4: 0.01265544 | AE4: Standard Error | AF4: 1.2285589
A5: Median | B5: 0 | C5: Median | D5: 0 | E5: Median | F5: 27.5 | G5: Median | H5: 14 | I5: Median | J5: 22 | K5: Median | L5: 3 | M5: Median | N5: 33 | O5: Median | P5: 0 | Q5: Median | R5: 0 | S5: Median | T5: 0 | U5: Median | V5: 0 | W5: Median | X5: 0 | Y5: Median | Z5: 0 | AA5: Median | AB5: -0.57615513 | AC5: Median | AD5: 0 | AE5: Median | AF5: 85
A6: Mode | B6: 0 | C6: Mode | D6: 0 | E6: Mode | F6: 28 | G6: Mode | H6: 18 | I6: Mode | J6: 20 | K6: Mode | L6: 2 | M6: Mode | N6: 30 | O6: Mode | P6: 0 | Q6: Mode | R6: 0 | S6: Mode | T6: 0 | U6: Mode | V6: 0 | W6: Mode | X6: 0 | Y6: Mode | Z6: 0 | AA6: Mode | AB6: -1.2607809 | AC6: Mode | AD6: 0 | AE6: Mode | AF6: 90
A7: Standard Deviation | B7: 0.48024018 | C7: Standard Deviation | D7: 0.48304589 | E7: Standard Deviation | F7: 3.9300567 | G7: Standard Deviation | H7: 8.8194933 | I7: Standard Deviation | J7: 8.5162742 | K7: Standard Deviation | L7: 1.9145821 | M7: Standard Deviation | N7: 26.393867 | O7: Standard Deviation | P7: 0.40020015 | Q7: Standard Deviation | R7: 0.3924972 | S7: Standard Deviation | T7: 0.32512414 | U7: Standard Deviation | V7: 0.27142895 | W7: Standard Deviation | X7: 0.27142895 | Y7: Standard Deviation | Z7: 0.43322937 | AA7: Standard Deviation | AB7: 3.8560908 | AC7: Standard Deviation | AD7: 0.40020015 | AE7: Standard Deviation | AF7: 38.850442
A8: Sample Variance | B8: 0.23063063 | C8: Sample Variance | D8: 0.23333333 | E8: Sample Variance | F8: 15.445345 | G8: Sample Variance | H8: 77.783462 | I8: Sample Variance | J8: 72.526927 | K8: Sample Variance | L8: 3.6656246 | M8: Sample Variance | N8: 696.63623 | O8: Sample Variance | P8: 0.16016016 | Q8: Sample Variance | R8: 0.15405405 | S8: Sample Variance | T8: 0.10570571 | U8: Sample Variance | V8: 0.073673674 | W8: Sample Variance | X8: 0.073673674 | Y8: Sample Variance | Z8: 0.18768769 | AA8: Sample Variance | AB8: 14.869436 | AC8: Sample Variance | AD8: 0.16016016 | AE8: Sample Variance | AF8: 1509.3569
A9: Kurtosis | B9: -1.6620267 | C9: Kurtosis | D9: -1.7125525 | E9: Kurtosis | F9: -0.91363551 | G9: Kurtosis | H9: -0.39452336 | I9: Kurtosis | J9: 0.40348009 | K9: Kurtosis | L9: -0.50032422 | M9: Kurtosis | N9: -0.215477 | O9: Kurtosis | P9: 0.2572786 | Q9: Kurtosis | R9: 0.5062475 | S9: Kurtosis | T9: 3.4931322 | U9: Kurtosis | V9: 7.6310524 | W9: Kurtosis | X9: 7.6310524 | Y9: Kurtosis | Z9: -0.66398796 | AA9: Kurtosis | AB9: -0.13862801 | AC9: Kurtosis | AD9: 0.2572786 | AE9: Kurtosis | AF9: -0.25403882
A10: Skewness | B10: 0.58421001 | C10: Skewness | D10: 0.5393298 | E10: Skewness | F10: 0.10690182 | G10: Skewness | H10: 0.60894205 | I10: Skewness | J10: 0.68456299 | K10: Skewness | L10: 0.64075946 | M10: Skewness | N10: 0.89773216 | O10: Skewness | P10: 1.5022543 | Q10: Skewness | R10: 1.5827947 | S10: Skewness | T10: 2.3422532 | U10: Skewness | V10: 3.1009344 | W10: Skewness | X10: 3.1009344 | Y10: Skewness | Z10: 1.1564359 | AA10: Skewness | AB10: 0.71495956 | AC10: Skewness | AD10: 1.5022543 | AE10: Skewness | AF10: 0.83630174
A11: Range | B11: 1 | C11: Range | D11: 1 | E11: Range | F11: 14 | G11: Range | H11: 38 | I11: Range | J11: 42 | K11: Range | L11: 7 | M11: Range | N11: 105 | O11: Range | P11: 1 | Q11: Range | R11: 1 | S11: Range | T11: 1 | U11: Range | V11: 1 | W11: Range | X11: 1 | Y11: Range | Z11: 1 | AA11: Range | AB11: 16.132298 | AC11: Range | AD11: 1 | AE11: Range | AF11: 160
A12: Minimum | B12: 0 | C12: Minimum | D12: 0 | E12: Minimum | F12: 21 | G12: Minimum | H12: 2 | I12: Minimum | J12: 8 | K12: Minimum | L12: 1 | M12: Minimum | N12: 5 | O12: Minimum | P12: 0 | Q12: Minimum | R12: 0 | S12: Minimum | T12: 0 | U12: Minimum | V12: 0 | W12: Minimum | X12: 0 | Y12: Minimum | Z12: 0 | AA12: Minimum | AB12: -5.63212 | AC12: Minimum | AD12: 0 | AE12: Minimum | AF12: 40
A13: Maximum | B13: 1 | C13: Maximum | D13: 1 | E13: Maximum | F13: 35 | G13: Maximum | H13: 40 | I13: Maximum | J13: 50 | K13: Maximum | L13: 8 | M13: Maximum | N13: 110 | O13: Maximum | P13: 1 | Q13: Maximum | R13: 1 | S13: Maximum | T13: 1 | U13: Maximum | V13: 1 | W13: Maximum | X13: 1 | Y13: Maximum | Z13: 1 | AA13: Maximum | AB13: 10.500178 | AC13: Maximum | AD13: 1 | AE13: Maximum | AF13: 200
A14: Sum | B14: 360 | C14: Sum | D14: 370 | E14: Sum | F14: 27510 | G14: Sum | H14: 15611 | I14: Sum | J14: 22560 | K14: Sum | L14: 3321 | M14: Sum | N14: 39898 | O14: Sum | P14: 200 | Q14: Sum | R14: 190 | S14: Sum | T14: 120 | U14: Sum | V14: 80 | W14: Sum | X14: 80 | Y14: Sum | Z14: 250 | AA14: Sum | AB14: 5.5622174e-14 | AC14: Sum | AD14: 200 | AE14: Sum | AF14: 95950
... A18: Confidence Level(95.0%) | B18: 0.029801153 | C18: Confidence Level(95.0%) | D18: 0.029975261 | E18: Confidence Level(95.0%) | F18: 0.24387843 | G18: Confidence Level(95.0%) | H18: 0.54729089 | I18: Confidence Level(95.0%) | J18: 0.52847472 | K18: Confidence Level(95.0%) | L18: 0.11880879 | M18: Confidence Level(95.0%) | N18: 1.6378631 | O18: Confidence Level(95.0%) | P18: 0.024834295 | Q18: Confidence Level(95.0%) | R18: 0.024356291 | S18: Confidence Level(95.0%) | T18: 0.020175476 | U18: Confidence Level(95.0%) | V18: 0.016843438 | W18: Confidence Level(95.0%) | X18: 0.016843438 | Y18: Confidence Level(95.0%) | Z18: 0.026883912 | AA18: Confidence Level(95.0%) | AB18: 0.2392885 | AC18: Confidence Level(95.0%) | AD18: 0.024834295 | AE18: Confidence Level(95.0%) | AF18: 2.410852
A21: BACK TO INDEX

Sheet Correlation Matrix
B1: Gender_Male | C1: Gender_Female | D1: Age | E1: Comments_Received_Per_Day | F1: Messages_Sent_Per_Day | G1: Posts_Per_Day | H1: Likes_Received_Per_Day | I1: Twitter_Platform | J1: Facebook_Platform | K1: LinkedIn_Platform | L1: Snapchat_Platform | M1: Whatsapp_Platform | N1: Instagram_Platform | O1: Engagement_Score_Per_Day | P1: Happiness_Emotion | Q1: Daily_Usage_Time (minutes)
A2: Gender_Male | B2: 1
A3: Gender_Female | B3: -0.57476703 | C3: 1
A4: Age | B4: 0.17841575 | C4: -0.020406018 | D4: 1
A5: Comments_Received_Per_Day | B5: 0.060984493 | C5: 0.28123621 | D5: 0.098808577 | E5: 1
A6: Messages_Sent_Per_Day | B6: 0.05076158 | C6: 0.25642164 | D6: 0.1075309 | E6: 0.88278299 | F6: 1
A7: Posts_Per_Day | B7: 0.011365866 | C7: 0.28815696 | D7: 0.028108693 | E7: 0.9173093 | F7: 0.8757084 | G7: 1
A8: Likes_Received_Per_Day | B8: 0.0076381692 | C8: 0.33507424 | D8: 0.058817669 | E8: 0.93105746 | F8: 0.91004552 | G8: 0.91781439 | H8: 1
A9: Twitter_Platform | B9: 0.19791667 | C9: -0.020712326 | D9: -0.10310351 | E9: 0.054679012 | F9: -0.081649292 | G9: 0.021947879 | H9: -0.088189582 | I9: 1
A10: Facebook_Platform | B10: -0.1508196 | C10: -0.31836614 | D10: -0.15373197 | E10: -0.38173137 | F10: -0.33372551 | G10: -0.34765447 | H10: -0.37033152 | I10: -0.24216105 | J10: 1
A11: LinkedIn_Platform | B11: 0.043594903 | C11: -0.028044621 | D11: 0.21841339 | E11: -0.41937291 | F11: -0.43389963 | G11: -0.3996434 | H11: -0.3782658 | I11: -0.18463724 | J11: -0.17884779 | K11: 1
A12: Snapchat_Platform | B12: -0.22116293 | C12: 0.0030538658 | D12: -0.13212415 | E12: -0.091525222 | F12: -0.02373063 | G12: -0.10725155 | H12: -0.10561004 | I12: -0.14744196 | J12: -0.1428188 | K12: -0.1088931 | L12: 1
A13: Whatsapp_Platform | B13: -0.067577563 | C13: 0.2320938 | D13: 0.064936015 | E13: -0.015003312 | F13: -0.015069816 | G13: -0.049465155 | H13: -0.038541851 | I13: -0.14744196 | J13: -0.1428188 | K13: -0.1088931 | L13: -0.086956522 | M13: 1
A14: Instagram_Platform | B14: -0.048112522 | C14: 0.3228732 | D14: 0.083778518 | E14: 0.73230777 | F14: 0.74257749 | G14: 0.74792691 | H14: 0.86171397 | I14: -0.28867513 | J14: -0.2796235 | K14: -0.21320072 | L14: -0.17025131 | M14: -0.17025131 | N14: 1
A15: Engagement_Score_Per_Day | B15: 0.033907425 | C15: 0.30105335 | D15: 0.076052628 | E15: 0.96759904 | F15: 0.95136166 | G15: 0.96233007 | H15: 0.97480002 | I15: -0.024172663 | J15: -0.37173473 | K15: -0.42301435 | L15: -0.085090694 | M15: -0.03062172 | N15: 0.79991015 | O15: 1
A16: Happiness_Emotion | B16: -0.010416667 | C16: 0.18641093 | D16: 0.049642433 | E16: 0.64174102 | F16: 0.59357273 | G16: 0.6229017 | H16: 0.67704884 | I16: -0.1875 | J16: -0.24216105 | K16: -0.18463724 | L16: -0.055290734 | M16: -0.055290734 | N16: 0.69282032 | O16: 0.65747007 | P16: 1
A17: Daily_Usage_Time (minutes) | B17: -0.031761555 | C17: 0.31995788 | D17: 0.087296577 | E17: 0.89692033 | F17: 0.91623409 | G17: 0.88920532 | H17: 0.94133951 | I17: -0.15709094 | J17: -0.2974049 | K17: -0.38150077 | L17: -0.045184485 | M17: -0.064169563 | N17: 0.85418255 | O17: 0.9449205 | P17: 0.7024025 | Q17: 1
A20: BACK TO INDEX

Sheet Model 1
A1: SUMMARY OUTPUT | E1: BACK TO INDEX
A3: Regression Statistics
A4: Multiple R | B4: 0.96371381
A5: R Square | B5: 0.9287443
A6: Adjusted R Square | B6: 0.92831375
A7: Standard Error | B7: 10.401929
A8: Observations | B8: 1000
A10: ANOVA
B11: df | C11: SS | D11: MS | E11: F | F11: Significance F
A12: Regression | B12: 6 | C12: 1400404.8 | D12: 233400.8 | E12: 2157.1212 | F12: 0
A13: Residual | B13: 993 | C13: 107442.73 | D13: 108.20013
A14: Total | B14: 999 | C14: 1507847.5
B16: Coefficients | C16: Standard Error | D16: t Stat | E16: P-value | F16: Lower 95% | G16: Upper 95% | H16: Lower 95.0% | I16: Upper 95.0%
A17: Intercept | B17: 27.911169 | C17: 1.2088632 | D17: 23.088775 | E17: 9.2999662e-95 | F17: 25.538949 | G17: 30.283389 | H17: 25.538949 | I17: 30.283389
A18: Instagram_Platform | B18: 21.695861 | C18: 1.7256964 | D18: 12.572235 | E18: 9.5884764e-34 | F18: 18.309431 | G18: 25.082292 | H18: 18.309431 | I18: 25.082292
A19: Posts_Per_Day | B19: 1.5110266 | C19: 0.48749478 | D19: 3.099575 | E19: 0.0019925595 | F19: 0.55438838 | G19: 2.4676648 | H19: 0.55438838 | I19: 2.4676648
A20: Likes_Received_Per_Day | B20: 0.2073184 | C20: 0.057516593 | D20: 3.6044973 | E20: 0.000328293 | F20: 0.09445038 | G20: 0.32018642 | H20: 0.09445038 | I20: 0.32018642
A21: Comments_Received_Per_Day | B21: 0.61774193 | C21: 0.12222907 | D21: 5.053969 | E21: 5.1496307e-07 | F21: 0.377885 | G21: 0.85759886 | H21: 0.377885 | I21: 0.85759886
A22: Messages_Sent_Per_Day | B22: 1.687042 | C22: 0.097985981 | D22: 17.217178 | E22: 2.4759973e-58 | F22: 1.4947587 | G22: 1.8793254 | H22: 1.4947587 | I22: 1.8793254
A23: Happiness_Emotion | B23: 8.1095947 | C23: 1.1881127 | D23: 6.8256105 | E23: 1.5215362e-11 | F23: 5.7780947 | G23: 10.441095 | H23: 5.7780947 | I23: 10.441095
A27: RESIDUAL OUTPUT | F27: PROBABILITY OUTPUT
A29: Observation | B29: Predicted Daily_Usage_Time (minutes) | C29: Residuals | D29: Standard Residuals | F29: Percentile | G29: Daily_Usage_Time (minutes)
A30: 1 | B30: 98.000957 | C30: 21.999043 | D30: 2.1212802 | F30: 0.05 | G30: 40
A31: 2 | B31: 105.66748 | C31: -15.66748 | D31: -1.5107527 | F31: 0.15 | G31: 40
A32: 3 | B32: 70.872549 | C32: -10.872549 | D32: -1.0483966 | F32: 0.25 | G32: 40
A33: 4 | B33: 185.31144 | C33: 14.688556 | D33: 1.416359 | F33: 0.35 | G33: 40
A34: 5 | B34: 48.564692 | C34: -3.5646918 | D34: -0.34372904 | F34: 0.45 | G34: 40
A35: 6 | B35: 127.64202 | C35: 22.357984 | D35: 2.1558914 | F35: 0.55 | G35: 40
A36: 7 | B36: 75.207977 | C36: 9.7920231 | D36: 0.94420579 | F36: 0.65 | G36: 40
A37: 8 | B37: 86.688117 | C37: 23.311883 | D37: 2.2478721 | F37: 0.75 | G37: 40
A38: 9 | B38: 48.355968 | C38: 6.6440317 | D38: 0.64065752 | F38: 0.85 | G38: 40
A39: 10 | B39: 153.25854 | C39: 16.74146 | D39: 1.6143123 | F39: 0.95 | G39: 40
A40: 11 | B40: 79.276454 | C40: -4.2764538 | D40: -0.41236142 | F40: 1.05 | G40: 45
A41: 12 | B41: 73.134793 | C41: 21.865207 | D41: 2.1083748 | F41: 1.15 | G41: 45
... A1029: 1000 | B1029: 90.482291 | C1029: 29.517709 | D1029: 2.8462751 | F1029: 99.95 | G1029: 200

Sheet Model 2
A1: SUMMARY OUTPUT | E1: BACK TO INDEX
A3: Regression Statistics
A4: Multiple R | B4: 0.96322998
A5: R Square | B5: 0.92781199
A6: Adjusted R Square | B6: 0.92744887
A7: Standard Error | B7: 10.464489
A8: Observations | B8: 1000
A10: ANOVA
B11: df | C11: SS | D11: MS | E11: F | F11: Significance F
A12: Regression | B12: 5 | C12: 1398999 | D12: 279799.8 | E12: 2555.12 | F12: 0
A13: Residual | B13: 994 | C13: 108848.51 | D13: 109.50554
A14: Total | B14: 999 | C14: 1507847.5
B16: Coefficients | C16: Standard Error | D16: t Stat | E16: P-value | F16: Lower 95% | G16: Upper 95% | H16: Lower 95.0% | I16: Upper 95.0%
A17: Intercept | B17: 27.044799 | C17: 1.1918523 | D17: 22.691401 | E17: 3.4882053e-92 | F17: 24.705963 | G17: 29.383634 | H17: 24.705963 | I17: 29.383634
A18: Happiness_Emotion | B18: 8.0397814 | C18: 1.1950996 | D18: 6.72729 | E18: 2.9133986e-11 | F18: 5.6945736 | G18: 10.384989 | H18: 5.6945736 | I18: 10.384989
A19: Posts_Per_Day | B19: 1.9715525 | C19: 0.47328397 | D19: 4.1656862 | E19: 3.3739907e-05 | F19: 1.0428021 | G19: 2.900303 | H19: 1.0428021 | I19: 2.900303
A20: Messages_Sent_Per_Day | B20: 1.8235766 | C20: 0.090911852 | D20: 20.058733 | E20: 2.0450441e-75 | F20: 1.6451754 | G20: 2.0019778 | H20: 1.6451754 | I20: 2.0019778
A21: Comments_Received_Per_Day | B21: 0.8440083 | C21: 0.10550904 | D21: 7.999393 | E21: 3.4628278e-15 | F21: 0.63696227 | G21: 1.0510543 | H21: 0.63696227 | I21: 1.0510543
A22: Instagram_Platform | B22: 25.736071 | C22: 1.3200103 | D22: 19.496871 | E22: 6.0614612e-72 | F22: 23.145744 | G22: 28.326397 | H22: 23.145744 | I22: 28.326397
A26: RESIDUAL OUTPUT | F26: PROBABILITY OUTPUT
A28: Observation | B28: Predicted Daily_Usage_Time (minutes) | C28: Residuals | D28: Standard Residuals | F28: Percentile | G28: Daily_Usage_Time (minutes)
A29: 1 | B29: 97.05831 | C29: 22.94169 | D29: 2.1978442 | F29: 0.05 | G29: 40
A30: 2 | B30: 112.71007 | C30: -22.710067 | D30: -2.1756544 | F30: 0.15 | G30: 40
A31: 3 | B31: 71.679477 | C31: -11.679477 | D31: -1.1189094 | F31: 0.25 | G31: 40
A32: 4 | B32: 185.05237 | C32: 14.947632 | D32: 1.4320029 | F32: 0.35 | G32: 40
A33: 5 | B33: 48.940134 | C33: -3.9401338 | D33: -0.37747003 | F33: 0.45 | G33: 40
A34: 6 | B34: 126.9564 | C34: 23.0436 | D34: 2.2076074 | F34: 0.55 | G34: 40
A35: 7 | B35: 74.223918 | C35: 10.776082 | D35: 1.0323629 | F35: 0.65 | G35: 40
A36: 8 | B36: 89.120898 | C36: 20.879102 | D36: 2.0002456 | F36: 0.75 | G36: 40
A37: 9 | B37: 48.108541 | C37: 6.8914586 | D37: 0.66021085 | F37: 0.85 | G37: 40
A38: 10 | B38: 151.38376 | C38: 18.61624 | D38: 1.7834604 | F38: 0.95 | G38: 40
A39: 11 | B39: 77.310599 | C39: -2.3105987 | D39: -0.22135841 | F39: 1.05 | G39: 45
A40: 12 | B40: 74.223918 | C40: 20.776082 | D40: 1.9903762 | F40: 1.15 | G40: 45
... A1028: 1000 | B1028: 90.241843 | C1028: 29.758157 | D1028: 2.8508708 | F1028: 99.95 | G1028: 200

Sheet Final Regression Model
A1: SUMMARY OUTPUT | E1: BACK TO INDEX
A3: Regression Statistics
A4: Multiple R | B4: 0.96036619
A5: R Square | B5: 0.92230322
A6: Adjusted R Square | B6: 0.9220692
A7: Standard Error | B7: 10.845524
A8: Observations | B8: 1000
A10: ANOVA
B11: df | C11: SS | D11: MS | E11: F | F11: Significance F
A12: Regression | B12: 3 | C12: 1390692.6 | D12: 463564.2 | E12: 3941.0215 | F12: 0
A13: Residual | B13: 996 | C13: 117154.89 | D13: 117.62539
A14: Total | B14: 999 | C14: 1507847.5
B16: Coefficients | C16: Standard Error | D16: t Stat | E16: P-value | F16: Lower 95% | G16: Upper 95% | H16: Lower 95.0% | I16: Upper 95.0%
A17: Intercept | B17: 89.174072 | C17: 0.48933962 | D17: 182.2335 | E17: 0 | F17: 88.213817 | G17: 90.134327 | H17: 88.213817 | I17: 90.134327
A18: Engagement_Score_Per_Day | B18: 7.110141 | C18: 0.15269192 | D18: 46.565275 | E18: 3.004439e-252 | F18: 6.8105062 | G18: 7.4097758 | H18: 6.8105062 | I18: 7.4097758
A19: Instagram_Platform | B19: 21.469633 | C19: 1.4200899 | D19: 15.118503 | E19: 1.2099614e-46 | F19: 18.682922 | G19: 24.256345 | H19: 18.682922 | I19: 24.256345
A20: Happiness_Emotion | B20: 7.0425969 | C20: 1.2243972 | D20: 5.7518892 | E20: 1.1734674e-08 | F20: 4.6399028 | G20: 9.445291 | H20: 4.6399028 | I20: 9.445291
A24: RESIDUAL OUTPUT | F24: PROBABILITY OUTPUT
A26: Observation | B26: Predicted Daily_Usage_Time (minutes) | C26: Residuals | D26: Standard Residuals | F26: Percentile | G26: Daily_Usage_Time (minutes)
A27: 1 | B27: 104.52869 | C27: 15.471307 | D27: 1.4286622 | F27: 0.05 | G27: 40
A28: 2 | B28: 103.82993 | C28: -13.829933 | D28: -1.2770932 | F28: 0.15 | G28: 40
A29: 3 | B29: 66.869387 | C29: -6.8693874 | D29: -0.63433773 | F29: 0.25 | G29: 40
A30: 4 | B30: 178.72019 | C30: 21.279815 | D30: 1.9650354 | F30: 0.35 | G30: 40
A31: 5 | B31: 49.694408 | C31: -4.6944076 | D31: -0.43349423 | F31: 0.45 | G31: 40
A32: 6 | B32: 127.16764 | C32: 22.832361 | D32: 2.1084017 | F32: 0.55 | G32: 40
A33: 7 | B33: 76.985003 | C33: 8.0149969 | D33: 0.74012639 | F33: 0.65 | G33: 40
A34: 8 | B34: 91.73103 | C34: 18.26897 | D34: 1.6870059 | F34: 0.75 | G34: 40
A35: 9 | B35: 53.891423 | C35: 1.1085768 | D35: 0.10236897 | F35: 0.85 | G35: 40
A36: 10 | B36: 148.64885 | C36: 21.351151 | D36: 1.9716228 | F36: 0.95 | G36: 40
A37: 11 | B37: 81.296834 | C37: -6.2968345 | D37: -0.58146665 | F37: 1.05 | G37: 45
A38: 12 | B38: 74.291142 | C38: 20.708858 | D38: 1.9123117 | F38: 1.15 | G38: 45
... A1026: 1000 | B1026: 93.181575 | C1026: 26.818425 | D1026: 2.4764856 | F1026: 99.95 | G1026: 200

Sheet MultiColl Test Model1
A1: SUMMARY OUTPUT | G1: BACK TO INDEX
A3: Regression Statistics
A4: Multiple R | B4: 0.11414866 | D4: VIF
A5: R Square | B5: 0.013029917 | D5: =1/(1-(B5)) -> 1.0132019
A6: Adjusted R Square | B6: 0.0080652785
A7: Standard Error | B7: 0.27033216
A8: Observations | B8: 1000
A10: ANOVA
B11: df | C11: SS | D11: MS | E11: F | F11: Significance F
A12: Regression | B12: 5 | C12: 0.95900187 | D12: 0.19180037 | E12: 2.624545 | F12: 0.022855036
A13: Residual | B13: 994 | C13: 72.640998 | D13: 0.073079475
A14: Total | B14: 999 | C14: 73.6
B16: Coefficients | C16: Standard Error | D16: t Stat | E16: P-value | F16: Lower 95% | G16: Upper 95% | H16: Lower 95.0% | I16: Upper 95.0%
A17: Intercept | B17: 0.046844324 | C17: 0.030902627 | D17: 1.5158687 | E17: 0.12987049 | F17: -0.013797551 | G17: 0.1074862 | H17: -0.013797551 | I17: 0.1074862
A18: Comments_Received_Per_Day | B18: 0.0070922325 | C18: 0.0029861202 | D18: 2.375066 | E18: 0.017734727 | F18: 0.0012324093 | G18: 0.012952056 | H18: 0.0012324093 | I18: 0.012952056
A19: Messages_Sent_Per_Day | B19: 0.0035398577 | C19: 0.0025360977 | D19: 1.3957892 | E19: 0.16308968 | F19: -0.0014368624 | G19: 0.0085165777 | H19: -0.0014368624 | I19: 0.0085165777
A20: Posts_Per_Day | B20: -0.029654551 | C20: 0.012657982 | D20: -2.3427549 | E20: 0.019338407 | F20: -0.054493986 | G20: -0.0048151154 | H20: -0.054493986 | I20: -0.0048151154
A21: Likes_Received_Per_Day | B21: -0.0012951888 | C21: 0.0011365427 | D21: -1.1395866 | E21: 0.25473311 | F21: -0.0035254872 | G21: 0.00093510961 | H21: -0.0035254872 | I21: 0.00093510961
A22: Happiness_Emotion | B22: -0.036310747 | C22: 0.029175194 | D22: -1.244576 | E22: 0.21358101 | F22: -0.09356279 | G22: 0.020941296 | H22: -0.09356279 | I22: 0.020941296
A25: SUMMARY OUTPUT
A27: Regression Statistics
A28: Multiple R | B28: 0.95225933 | D28: VIF
A29: R Square | B29: 0.90679784 | D29: =1/(1-(B29)) -> 10.729365
A30: Adjusted R Square | B30: 0.90632901
A31: Standard Error | B31: 2.6992691
A32: Observations | B32: 1000
A34: ANOVA
B35: df | C35: SS | D35: MS | E35: F | F35: Significance F
A36: Regression | B36: 5 | C36: 70463.342 | D36: 14092.668 | E36: 1934.1977 | F36: 0
A37: Residual | B37: 994 | C37: 7242.3375 | D37: 7.2860538
A38: Total | B38: 999 | C38: 77705.679
B40: Coefficients | C40: Standard Error | D40: t Stat | E40: P-value | F40: Lower 95% | G40: Upper 95% | H40: Lower 95.0% | I40: Upper 95.0%
A41: Intercept | B41: 0.10389492 | C41: 0.31367902 | D41: 0.33121412 | E41: 0.74055256 | F41: -0.51165418 | G41: 0.71944403 | H41: -0.51165418 | I41: 0.71944403
A42: Messages_Sent_Per_Day | B42: 0.088343231 | C42: 0.025272199 | D42: 3.4956686 | E42: 0.00049375707 | F42: 0.038750245 | G42: 0.13793622 | H42: 0.038750245 | I42: 0.13793622
A43: Posts_Per_Day | B43: 1.4335453 | C43: 0.11804939 | D43: 12.143606 | E43: 9.690382e-32 | F43: 1.2018907 | G43: 1.6651999 | H43: 1.2018907 | I43: 1.6651999
A44: Likes_Received_Per_Day | B44: 0.24166816 | C44: 0.012806677 | D44: 18.870481 | E44: 3.9928316e-68 | F44: 0.21653693 | G44: 0.26679939 | H44: 0.21653693 | I44: 0.26679939
A45: Happiness_Emotion | B45: 1.5748936 | C45: 0.30423809 | D45: 5.1765168 | E45: 2.7351339e-07 | F45: 0.97787092 | G45: 2.1719163 | H45: 0.97787092 | I45: 2.1719163
A46: Instagram_Platform | B46: -4.8151088 | C46: 0.42096467 | D46: -11.438273 | E46: 1.5036014e-28 | F46: -5.6411903 | G46: -3.9890274 | H46: -5.6411903 | I46: -3.9890274
A49: SUMMARY OUTPUT
A51: Regression Statistics
...

Sheet MultiColl Test Model2
A1: SUMMARY OUTPUT | G1: BACK TO INDEX
A3: Regression Statistics
A4: Multiple R | B4: 0.72167153 | D4: VIF
A5: R Square | B5: 0.5208098 | D5: =1/(1-(B5)) -> 2.086854
A6: Adjusted R Square | B6: 0.5188834
A7: Standard Error | B7: 0.2775891
A8: Observations | B8: 1000
A10: ANOVA
B11: df | C11: SS | D11: MS | E11: F | F11: Significance F
A12: Regression | B12: 4 | C12: 83.329568 | D12: 20.832392 | E12: 270.35494 | F12: 2.93657e-157
A13: Residual | B13: 995 | C13: 76.670432 | D13: 0.077055711
A14: Total | B14: 999 | C14: 160
B16: Coefficients | C16: Standard Error | D16: t Stat | E16: P-value | F16: Lower 95% | G16: Upper 95% | H16: Lower 95.0% | I16: Upper 95.0%
A17: Intercept | B17: -0.068575384 | C17: 0.03154116 | D17: -2.1741554 | E17: 0.029928564 | F17: -0.13047021 | G17: -0.0066805561 | H17: -0.13047021 | I17: -0.0066805561
A18: Posts_Per_Day | B18: 0.0037503237 | C18: 0.012554132 | D18: 0.29873222 | E18: 0.76520675 | F18: -0.02088529 | G18: 0.028385938 | H18: -0.02088529 | I18: 0.028385938
A19: Messages_Sent_Per_Day | B19: -0.004689304 | C19: 0.0024070114 | D19: -1.9481852 | E19: 0.051673674 | F19: -0.0094127052 | G19: 3.4097277e-05 | H19: -0.0094127052 | I19: 3.4097277e-05
A20: Comments_Received_Per_Day | B20: 0.015810959 | C20: 0.0027535646 | D20: 5.741997 | E20: 1.2421478e-08 | F20: 0.010407499 | G20: 0.02121442 | H20: 0.010407499 | I20: 0.02121442
A21: Instagram_Platform | B21: 0.46034548 | C21: 0.03182939 | D21: 14.462906 | E21: 3.5871204e-43 | F21: 0.39788505 | G21: 0.52280592 | H21: 0.39788505 | I21: 0.52280592
A24: SUMMARY OUTPUT
A26: Regression Statistics
A27: Multiple R | B27: 0.93086019 | D27: VIF
A28: R Square | B28: 0.86650069 | D28: =1/(1-(B28)) -> 7.4906755
A29: Adjusted R Square | B29: 0.86596401
A30: Standard Error | B30: 0.70094623
A31: Observations | B31: 1000
A33: ANOVA
B34: df | C34: SS | D34: MS | E34: F | F34: Significance F
A35: Regression | B35: 4 | C35: 3173.09 | D35: 793.2725 | E35: 1614.5555 | F35: 0
A36: Residual | B36: 995 | C36: 488.86899 | D36: 0.49132562
A37: Total | B37: 999 | C37: 3661.959
B39: Coefficients | C39: Standard Error | D39: t Stat | E39: P-value | F39: Lower 95% | G39: Upper 95% | H39: Lower 95.0% | I39: Upper 95.0%
A40: Intercept | B40: -0.15054961 | C40: 0.079691432 | D40: -1.8891568 | E40: 0.059161403 | F40: -0.30693217 | G40: 0.005832955 | H40: -0.30693217 | I40: 0.005832955
A41: Happiness_Emotion | B41: 0.02391296 | C41: 0.080048145 | D41: 0.29873222 | E41: 0.76520675 | F41: -0.1331696 | G41: 0.18099552 | H41: -0.1331696 | I41: 0.18099552
A42: Messages_Sent_Per_Day | B42: 0.056245963 | C42: 0.0058226668 | D42: 9.6598285 | E42: 3.6635315e-21 | F42: 0.044819847 | G42: 0.067672079 | H42: 0.044819847 | I42: 0.067672079
A43: Comments_Received_Per_Day | B43: 0.13300329 | C43: 0.0056717377 | D43: 23.450184 | E43: 3.663812e-97 | F43: 0.12187335 | G43: 0.14413323 | H43: 0.12187335 | I43: 0.14413323
A44: Instagram_Platform | B44: 0.48617492 | C44: 0.087064962 | D44: 5.5840479 | E44: 3.0309721e-08 | F44: 0.3153229 | G44: 0.65702694 | H44: 0.3153229 | I44: 0.65702694
A47: SUMMARY OUTPUT
A49: Regression Statistics
A50: Multiple R | B50: 0.90395526 | D50: VIF
A51: R Square | B51: 0.81713511 | D51: =1/(1-(B51)) -> 5.4685185
...

Sheet Multicollinearity Test (Final)
A1: SUMMARY OUTPUT | F1: BACK TO INDEX | R1: SUMMARY OUTPUT | AI1: SUMMARY OUTPUT
A3: Regression Statistics | R3: Regression Statistics | AI3: Regression Statistics
A4: Multiple R | B4: 0.8126301 | D4: VIF | R4: Multiple R | S4: 0.83001375 | U4: VIF | AI4: Multiple R | AJ4: 0.7138738 | AL4: VIF
A5: R Square | B5: 0.66036768 | D5: =1/(1-(B5)) -> 2.9443605 | R5: R Square | S5: 0.68892283 | U5: =1/(1-(S5)) -> 3.2146364 | AI5: R Square | AJ5: 0.5096158 | AL5: =1/(1-(AJ5)) -> 2.0392174
A6: Adjusted R Square | B6: 0.65968637 | R6: Adjusted R Square | S6: 0.6882988 | AI6: Adjusted R Square | AJ6: 0.50863208
A7: Standard Error | B7: 2.2495048 | R7: Standard Error | S7: 0.24187285 | AI7: Standard Error | AJ7: 0.28053086
A8: Observations | B8: 1000 | R8: Observations | S8: 1000 | AI8: Observations | AJ8: 1000
A10: ANOVA | R10: ANOVA | AI10: ANOVA
B11: df | C11: SS | D11: MS | E11: F | F11: Significance F | S11: df | T11: SS | U11: MS | V11: F | W11: Significance F | AJ11: df | AK11: SS | AL11: MS | AM11: F | AN11: Significance F
A12: Regression | B12: 2 | C12: 9809.4757 | D12: 4904.7378 | E12: 969.26371 | F12: 1.6143381e-234 | R12: Regression | S12: 2 | T12: 129.17303 | U12: 64.586515 | V12: 1103.9962 | W12: 1.5659163e-253 | AI12: Regression | AJ12: 2 | AK12: 81.538528 | AL12: 40.769264 | AM12: 518.04988 | AN12: 5.4004416e-155
A13: Residual | B13: 997 | C13: 5045.091 | D13: 5.0602718 | R13: Residual | S13: 997 | T13: 58.32697 | U13: 0.058502477 | AI13: Residual | AJ13: 997 | AK13: 78.461472 | AL13: 0.078697565
A14: Total | B14: 999 | C14: 14854.567 | R14: Total | S14: 999 | T14: 187.5 | AI14: Total | AJ14: 999 | AK14: 160
B16: Coefficients | C16: Standard Error | D16: t Stat | E16: P-value | F16: Lower 95% | G16: Upper 95% | H16: Lower 95.0% | I16: Upper 95.0% | S16: Coefficients | T16: Standard Error | U16: t Stat | V16: P-value | W16: Lower 95% | X16: Upper 95% | Y16: Lower 95.0% | Z16: Upper 95.0% | AJ16: Coefficients | AK16: Standard Error | AL16: t Stat | AM16: P-value | AN16: Lower 95% | AO16: Upper 95% | AP16: Lower 95.0% | AQ16: Upper 95.0%
A17: Intercept | B17: -1.856508 | C17: 0.082730539 | D17: -22.44042 | E17: 1.3309524e-90 | F17: -2.018854 | G17: -1.6941621 | H17: -2.018854 | I17: -1.6941621 | R17: Intercept | S17: 0.18635102 | T17: 0.0091795377 | U17: 20.300698 | V17: 5.8563464e-77 | W17: 0.16833759 | X17: 0.20436445 | Y17: 0.16833759 | Z17: 0.20436445 | AI17: Intercept | AJ17: 0.092974195 | AK17: 0.01231002 | AL17: 7.5527249 | AM17: 9.617067e-14 | AN17: 0.068817674 | AO17: 0.11713072 | AP17: 0.068817674 | AQ17: 0.11713072
A18: Instagram_Platform | B18: 5.8950986 | C18: 0.22781621 | D18: 25.876555 | E18: 2.3278186e-113 | F18: 5.4480443 | G18: 6.3421529 | H18: 5.4480443 | I18: 6.3421529 | R18: Happiness_Emotion | S18: 0.3182449 | T18: 0.025377862 | U18: 12.540257 | V18: 1.330918e-33 | W18: 0.26844475 | X18: 0.36804505 | Y18: 0.26844475 | Z18: 0.36804505 | AI18: Instagram_Platform | AJ18: 0.42810322 | AK18: 0.034138314 | AL18: 12.540257 | AM18: 1.330918e-33 | AN18: 0.36111203 | AO18: 0.49509441 | AP18: 0.36111203 | AQ18: 0.49509441
A19: Happiness_Emotion | B19: 1.9136669 | C19: 0.24661828 | D19: 7.7596313 | E19: 2.1016649e-14 | F19: 1.4297165 | G19: 2.3976174 | H19: 1.4297165 | I19: 2.3976174 | R19: Engagement_Score_Per_Day | S19: 0.068154021 | T19: 0.0026338135 | U19: 25.876555 | V19: 2.3278186e-113 | W19: 0.062985567 | X19: 0.073322475 | Y19: 0.062985567 | Z19: 0.073322475 | AI19: Engagement_Score_Per_Day | AJ19: 0.02976143 | AK19: 0.003835418 | AL19: 7.7596313 | AM19: 2.1016649e-14 | AN19: 0.022235012 | AO19: 0.037287848 | AP19: 0.022235012 | AQ19: 0.037287848
A23: RESIDUAL OUTPUT | F23: PROBABILITY OUTPUT | R23: RESIDUAL OUTPUT | W23: PROBABILITY OUTPUT | AI23: RESIDUAL OUTPUT | AN23: PROBABILITY OUTPUT
A25: Observation | B25: Predicted Engagement_Score_Per_Day | C25: Residuals | D25: Standard Residuals | F25: Percentile | G25: Engagement_Score_Per_Day | R25: Observation | S25: Predicted Instagram_Platform | T25: Residuals | U25: Standard Residuals | W25: Percentile | X25: Instagram_Platform | AI25: Observation | AJ25: Predicted Happiness_Emotion | AK25: Residuals | AL25: Standard Residuals | AN25: Percentile | AO25: Happiness_Emotion
A26: 1 | B26: 5.9522575 | C26: -7.8027988 | D26: -3.4721514 | F26: 0.05 | G26: -5.63212 | R26: 1 | S26: 0.37847409 | T26: 0.62152591 | U26: 2.5722151 | W26: 0.05 | X26: 0 | AI26: 1 | AJ26: 0.46600266 | AK26: 0.53399734 | AL26: 1.9054327 | AN26: 0.05 | AO26: 0
A27: 2 | B27: -1.856508 | C27: 3.9177696 | D27: 1.7433602 | F27: 0.15 | G27: -5.5525853 | R27: 2 | S27: 0.32683429 | T27: -0.32683429 | U27: -1.3526195 | W27: 0.15 | X27: 0 | AI27: 2 | AJ27: 0.15432029 | AK27: -0.15432029 | AL27: -0.55065241 | AN27: 0.15 | AO27: 0
A28: 3 | B28: -1.856508 | C28: -1.2805162 | D28: -0.56981429 | F28: 0.25 | G28: -5.5525853 | R28: 3 | S28: -0.027449797 | T28: 0.027449797 | U28: 0.11360231 | W28: 0.25 | X28: 0 | AI28: 3 | AJ28: -0.00038813297 | AK28: 0.00038813297 | AL28: 0.0013849531 | AN28: 0.25 | AO28: 0
A29: 4 | B29: 4.0385906 | C29: 5.5359706 | D29: 2.4634401 | F29: 0.35 | G29: -5.4389226 | R29: 4 | S29: 0.83889586 | T29: 0.16110414 | U29: 0.6667373 | W29: 0.35 | X29: 0 | AI29: 4 | AJ29: 0.80603004 | AK29: -0.80603004 | AL29: -2.8761117 | AN29: 0.35 | AO29: 0
A30: 5 | B30: -1.856508 | C30: -3.6960773 | D30: -1.6447098 | F30: 0.45 | G30: -5.4013126 | R30: 5 | S30: -0.19208 | T30: 0.19208 | U30: 0.79493236 | W30: 0.45 | X30: 0 | AI30: 5 | AJ30: -0.072278685 | AK30: 0.072278685 | AL30: 0.25790797 | AN30: 0.45 | AO30: 0
A31: 6 | B31: 5.9522575 | C31: -4.6187627 | D31: -2.0552937 | F31: 0.55 | G31: -5.2836128 | R31: 6 | S31: 0.59547896 | T31: 0.40452104 | U31: 1.6741299 | W31: 0.55 | X31: 0 | AI31: 6 | AJ31: 0.56076413 | AK31: 0.43923587 | AL31: 1.5673007 | AN31: 0.55 | AO31: 0
A32: 7 | B32: -1.856508 | C32: 0.1421863 | D32: 0.063271188 | F32: 0.65 | G32: -5.2121522 | R32: 7 | S32: 0.069513101 | T32: -0.069513101 | U32: -0.28768333 | W32: 0.65 | X32: 0 | AI32: 7 | AJ32: 0.041953529 | AK32: -0.041953529 | AL32: -0.14970042 | AN32: 0.65 | AO32: 0
A33: 8 | B33: -1.856508 | C33: 2.2161293 | D33: 0.98615081 | F33: 0.75 | G33: -5.2040781 | R33: 8 | S33: 0.21086065 | T33: -0.21086065 | U33: -0.87265702 | W33: 0.75 | X33: 0 | AI33: 8 | AJ33: 0.10367704 | AK33: -0.10367704 | AL33: -0.36994495 | AN33: 0.75 | AO33: 0
A34: 9 | B34: -1.856508 | C34: -3.1057915 | D34: -1.3820398 | F34: 0.85 | G34: -5.1742646 | R34: 9 | S34: -0.15184964 | T34: 0.15184964 | U34: 0.62843709 | W34: 0.85 | X34: 0 | AI34: 9 | AJ34: -0.054710934 | AK34: 0.054710934 | AL34: 0.19522195 | AN34: 0.85 | AO34: 0
A35: 10 | B35: 5.9522575 | C35: -1.5975553 | D35: -0.71089284 | F35: 0.95 | G35: -5.1742646 | R35: 10 | S35: 0.80138638 | T35: 0.19861362 | U35: 0.82197206 | W35: 0.95 | X35: 0 | AI35: 10 | AJ35: 0.65067958 | AK35: 0.34932042 | AL35: 1.2464604 | AN35: 0.95 | AO35: 0
A36: 11 | B36: -1.856508 | C36: 0.74862032 | D36: 0.33312701 | F36: 1.05 | G36: -5.1742646 | R36: 11 | S36: 0.11084402 | T36: -0.11084402 | U36: -0.45873333 | W36: 1.05 | X36: 0 | AI36: 11 | AJ36: 0.060001873 | AK36: -0.060001873 | AL36: -0.21410131 | AN36: 1.05 | AO36: 0
A37: 12 | B37: -1.856508 | C37: -0.23668959 | D37: -0.10532402 | F37: 1.15 | G37: -5.1742646 | R37: 12 | S37: 0.043691186 | T37: -0.043691186 | U37: -0.18081809 | W37: 1.15 | X37: 0 | AI37: 12 | AJ37: 0.030677641 | AK37: -0.030677641 | AL37: -0.1094653 | AN37: 1.15 | AO37: 0
... A1025: 1000 | B1025: -1.856508 | C1025: 2.4201399 | D1025: 1.0769331 | F1025: 99.95 | G1025: 10.500178 | R1025: 1000 | S1025: 0.2247648 | T1025: -0.2247648 | U1025: -0.9302 | W1025: 99.95 | X1025: 1 | AI1025: 1000 | AJ1025: 0.10974869 | AK1025: -0.10974869 | AL1025: -0.39161007 | AN1025: 99.95 | AO1025: 1

Sheet Multicollinearity Results
A1: Multicollinearity exists between | C1: BACK TO INDEX
A2: Posts_Per_Day | E2: Hence, a standardized calculated variable "Engagement_Score_Per_Day) is created to handle multicollinearity (final regression model) To test multicollinearity, VIF (Variance Inflation Factor) is used; It is a measure used in regression analysis to detect the presence and severity of multicollinearity The predictors are not excessively correlated. Each variable contributes information to the model, and the risk of unstable or misleading regression coefficients is very low. These values showcase a interpretable model with low multicollinearity.
A3: Likes_Received_Per_Day
A4: Comments_Received_Per_Day
A5: Messages_Sent_Per_Day
A7: MODEL 1 Multicollinearity Test Results | E7: MODEL 2 Multicollinearity Test Results | I7: MODEL 3 Multicollinearity Test Results
A8: Independent Variable | B8: Dependent Variable | C8: VIF Score | E8: Independent Variable | F8: Dependent Variable | G8: VIF Score | I8: Independent Variable | J8: Dependent Variable | K8: VIF Score
A9: Instagram_Platform | B9: Posts_Per_Day Likes_Received_Per_Day Comments_Received_Per_Day Messages_Sent_Per_Day Happiness_Emotion | C9: ='MultiColl Test Model1'!D5 -> 1.0132019 | E9: Happiness_Emotion | F9: Posts_Per_Day Messages_Sent_Per_Day Comments_Received_Per_Day Instagram_Platform | G9: ='MultiColl Test Model2'!D5 -> 2.086854 | I9: Engagement_Score_Per_Day | J9: Happiness_Emotion Instagram_Platform | K9: ='Multicollinearity Test (Final)'!D5 -> 2.9443605
A10: Comments_Received_Per_Day | B10: Instagram_Platform Posts_Per_Day Likes_Received_Per_Day Messages_Sent_Per_Day Happiness_Emotion | C10: ='MultiColl Test Model1'!D29 -> 10.729365 | E10: Posts_Per_Day | F10: Happiness_Emotion Messages_Sent_Per_Day Comments_Received_Per_Day Instagram_Platform | G10: ='MultiColl Test Model2'!D28 -> 7.4906755 | I10: Instagram_Platform | J10: Happiness_Emotion Engagement_Score_Per_Day | K10: ='Multicollinearity Test (Final)'!U5 -> 3.2146364
A11: Messages_Sent_Per_Day | B11: Instagram_Platform Posts_Per_Day Likes_Received_Per_Day Comments_Received_Per_Day Happiness_Emotion | C11: ='MultiColl Test Model1'!D53 -> 6.4293176 | E11: Messages_Sent_Per_Day | F11: Happiness_Emotion Posts_Per_Day Comments_Received_Per_Day Instagram_Platform | G11: ='MultiColl Test Model2'!D51 -> 5.4685185 | I11: Happiness_Emotion | J11: Instagram_Platform Engagement_Score_Per_Day | K11: ='Multicollinearity Test (Final)'!AL5 -> 2.0392174
A12: Posts_Per_Day | B12: Instagram_Platform Likes_Received_Per_Day Comments_Received_Per_Day Messages_Sent_Per_Day Happiness_Emotion | C12: ='MultiColl Test Model1'!D77 -> 8.0431401 | E12: Comments_Received_Per_Day | F12: Happiness_Emotion Posts_Per_Day Messages_Sent_Per_Day Instagram_Platform | G12: ='MultiColl Test Model2'!D74 -> 7.8994352
A13: Likes_Received_Per_Day | B13: Instagram_Platform Posts_Per_Day Comments_Received_Per_Day Messages_Sent_Per_Day Happiness_Emotion | C13: ='MultiColl Test Model1'!D101 -> 21.277964 | E13: Instagram_Platform | F13: Happiness_Emotion Posts_Per_Day Messages_Sent_Per_Day Comments_Received_Per_Day | G13: ='MultiColl Test Model2'!D97 -> 2.9834573
A14: Happiness_Emotion | B14: Instagram_Platform Posts_Per_Day Likes_Received_Per_Day Comments_Received_Per_Day Messages_Sent_Per_Day | C14: ='MultiColl Test Model1'!D125 -> 2.0874087
